 * Running on http://0.0.0.0:5000/ (Press CTRL+C to quit)
 * Restarting with stat
 * Debugger is active!
 * Debugger PIN: 198-088-730
pbkdf2:sha256:50000$RubLfaYR$6e7087eedef16398b1a184c9438934b3b94cde5e7fa983454515dfb0cf1000cd
pbkdf2:sha256:50000$k3NvQzMk$081b40e015251f6fa9c809af0d681000345c86863267404283b3ae4b5333adcc
 * Running on http://0.0.0.0:5000/ (Press CTRL+C to quit)
 * Restarting with stat
 * Debugger is active!
 * Debugger PIN: 198-088-730
127.0.0.1 - - [30/Jun/2017 22:31:08] "GET /admin/login/ HTTP/1.1" 200 -
127.0.0.1 - - [30/Jun/2017 22:31:29] "GET /admin/login/ HTTP/1.1" 200 -
127.0.0.1 - - [30/Jun/2017 22:37:21] "GET /push/test HTTP/1.1" 404 -
127.0.0.1 - - [30/Jun/2017 22:37:31] "GET /test HTTP/1.1" 200 -
127.0.0.1 - - [30/Jun/2017 22:55:01] "GET /test HTTP/1.1" 200 -
127.0.0.1 - - [30/Jun/2017 22:55:20] "GET /test HTTP/1.1" 200 -
pbkdf2:sha256:50000$rg0sL3Gl$f25105d41bc5e3f41b5fac1f40d4fe79649851809955f002dcf2ad0e7c75b56f
pbkdf2:sha256:50000$KxoDrEeQ$9acd7d50231caf1b40a2045d54d75d4480189ad0814aa63eed0a0c6e25d852bd
 * Running on http://0.0.0.0:5000/ (Press CTRL+C to quit)
 * Restarting with stat
 * Debugger is active!
 * Debugger PIN: 198-088-730
127.0.0.1 - - [30/Jun/2017 23:40:46] "GET /test HTTP/1.1" 200 -
 * Detected change in '/webser/python/recmdcstbao/myapp/views/push.py', reloading
pbkdf2:sha256:50000$zEBLQZsA$064875b9398a7146099cd67a84af75350d5e693d2d2430daf902b659cb6d710a
 * Restarting with stat
 * Debugger is active!
 * Debugger PIN: 198-088-730
127.0.0.1 - - [30/Jun/2017 23:43:07] "GET /test HTTP/1.1" 500 -
Traceback (most recent call last):
  File "/Library/Python/2.7/site-packages/flask/app.py", line 1997, in __call__
    return self.wsgi_app(environ, start_response)
  File "/Library/Python/2.7/site-packages/flask/app.py", line 1985, in wsgi_app
    response = self.handle_exception(e)
  File "/Library/Python/2.7/site-packages/flask/app.py", line 1540, in handle_exception
    reraise(exc_type, exc_value, tb)
  File "/Library/Python/2.7/site-packages/flask/app.py", line 1982, in wsgi_app
    response = self.full_dispatch_request()
  File "/Library/Python/2.7/site-packages/flask/app.py", line 1614, in full_dispatch_request
    rv = self.handle_user_exception(e)
  File "/Library/Python/2.7/site-packages/flask/app.py", line 1517, in handle_user_exception
    reraise(exc_type, exc_value, tb)
  File "/Library/Python/2.7/site-packages/flask/app.py", line 1612, in full_dispatch_request
    rv = self.dispatch_request()
  File "/Library/Python/2.7/site-packages/flask/app.py", line 1598, in dispatch_request
    return self.view_functions[rule.endpoint](**req.view_args)
  File "/webser/python/recmdcstbao/myapp/views/push.py", line 23, in test
    UserModel.query.filter_by(login='fdsf').first()
  File "/Library/Python/2.7/site-packages/flask_sqlalchemy/__init__.py", line 498, in __get__
    return type.query_class(mapper, session=self.sa.session())
  File "/Library/Python/2.7/site-packages/sqlalchemy/orm/scoping.py", line 78, in __call__
    return self.registry()
  File "/Library/Python/2.7/site-packages/sqlalchemy/util/_collections.py", line 990, in __call__
    return self.registry.setdefault(key, self.createfunc())
  File "/Library/Python/2.7/site-packages/sqlalchemy/orm/session.py", line 2861, in __call__
    return self.class_(**local_kw)
  File "/Library/Python/2.7/site-packages/flask_sqlalchemy/__init__.py", line 145, in __init__
    bind = options.pop('bind', None) or db.engine
  File "/Library/Python/2.7/site-packages/flask_sqlalchemy/__init__.py", line 922, in engine
    return self.get_engine()
  File "/Library/Python/2.7/site-packages/flask_sqlalchemy/__init__.py", line 941, in get_engine
    return connector.get_engine()
  File "/Library/Python/2.7/site-packages/flask_sqlalchemy/__init__.py", line 543, in get_engine
    self._engine = rv = sqlalchemy.create_engine(info, **options)
  File "/Library/Python/2.7/site-packages/sqlalchemy/engine/__init__.py", line 387, in create_engine
    return strategy.create(*args, **kwargs)
  File "/Library/Python/2.7/site-packages/sqlalchemy/engine/strategies.py", line 80, in create
    dbapi = dialect_cls.dbapi(**dbapi_args)
  File "/Library/Python/2.7/site-packages/sqlalchemy/dialects/mysql/pymysql.py", line 62, in dbapi
    return __import__('pymysql')
ImportError: No module named pymysql
127.0.0.1 - - [30/Jun/2017 23:43:07] "GET /test?__debugger__=yes&cmd=resource&f=style.css HTTP/1.1" 200 -
127.0.0.1 - - [30/Jun/2017 23:43:07] "GET /test?__debugger__=yes&cmd=resource&f=jquery.js HTTP/1.1" 200 -
127.0.0.1 - - [30/Jun/2017 23:43:07] "GET /test?__debugger__=yes&cmd=resource&f=debugger.js HTTP/1.1" 200 -
127.0.0.1 - - [30/Jun/2017 23:43:07] "GET /test?__debugger__=yes&cmd=resource&f=ubuntu.ttf HTTP/1.1" 200 -
127.0.0.1 - - [30/Jun/2017 23:43:07] "GET /test?__debugger__=yes&cmd=resource&f=console.png HTTP/1.1" 200 -
127.0.0.1 - - [30/Jun/2017 23:43:07] "GET /test?__debugger__=yes&cmd=resource&f=console.png HTTP/1.1" 200 -
127.0.0.1 - - [30/Jun/2017 23:43:46] "GET /test HTTP/1.1" 500 -
Traceback (most recent call last):
  File "/Library/Python/2.7/site-packages/flask/app.py", line 1997, in __call__
    return self.wsgi_app(environ, start_response)
  File "/Library/Python/2.7/site-packages/flask/app.py", line 1985, in wsgi_app
    response = self.handle_exception(e)
  File "/Library/Python/2.7/site-packages/flask/app.py", line 1540, in handle_exception
    reraise(exc_type, exc_value, tb)
  File "/Library/Python/2.7/site-packages/flask/app.py", line 1982, in wsgi_app
    response = self.full_dispatch_request()
  File "/Library/Python/2.7/site-packages/flask/app.py", line 1614, in full_dispatch_request
    rv = self.handle_user_exception(e)
  File "/Library/Python/2.7/site-packages/flask/app.py", line 1517, in handle_user_exception
    reraise(exc_type, exc_value, tb)
  File "/Library/Python/2.7/site-packages/flask/app.py", line 1612, in full_dispatch_request
    rv = self.dispatch_request()
  File "/Library/Python/2.7/site-packages/flask/app.py", line 1598, in dispatch_request
    return self.view_functions[rule.endpoint](**req.view_args)
  File "/webser/python/recmdcstbao/myapp/views/push.py", line 23, in test
    UserModel.query.filter_by(login='fdsf').first()
  File "/Library/Python/2.7/site-packages/sqlalchemy/orm/query.py", line 2755, in first
    ret = list(self[0:1])
  File "/Library/Python/2.7/site-packages/sqlalchemy/orm/query.py", line 2547, in __getitem__
    return list(res)
  File "/Library/Python/2.7/site-packages/sqlalchemy/orm/query.py", line 2855, in __iter__
    return self._execute_and_instances(context)
  File "/Library/Python/2.7/site-packages/sqlalchemy/orm/query.py", line 2878, in _execute_and_instances
    result = conn.execute(querycontext.statement, self._params)
  File "/Library/Python/2.7/site-packages/sqlalchemy/engine/base.py", line 945, in execute
    return meth(self, multiparams, params)
  File "/Library/Python/2.7/site-packages/sqlalchemy/sql/elements.py", line 263, in _execute_on_connection
    return connection._execute_clauseelement(self, multiparams, params)
  File "/Library/Python/2.7/site-packages/sqlalchemy/engine/base.py", line 1053, in _execute_clauseelement
    compiled_sql, distilled_params
  File "/Library/Python/2.7/site-packages/sqlalchemy/engine/base.py", line 1189, in _execute_context
    context)
  File "/Library/Python/2.7/site-packages/sqlalchemy/engine/base.py", line 1402, in _handle_dbapi_exception
    exc_info
  File "/Library/Python/2.7/site-packages/sqlalchemy/util/compat.py", line 203, in raise_from_cause
    reraise(type(exception), exception, tb=exc_tb, cause=cause)
  File "/Library/Python/2.7/site-packages/sqlalchemy/engine/base.py", line 1182, in _execute_context
    context)
  File "/Library/Python/2.7/site-packages/sqlalchemy/engine/default.py", line 470, in do_execute
    cursor.execute(statement, parameters)
  File "/Library/Python/2.7/site-packages/pymysql/cursors.py", line 166, in execute
    result = self._query(query)
  File "/Library/Python/2.7/site-packages/pymysql/cursors.py", line 322, in _query
    conn.query(q)
  File "/Library/Python/2.7/site-packages/pymysql/connections.py", line 856, in query
    self._affected_rows = self._read_query_result(unbuffered=unbuffered)
  File "/Library/Python/2.7/site-packages/pymysql/connections.py", line 1057, in _read_query_result
    result.read()
  File "/Library/Python/2.7/site-packages/pymysql/connections.py", line 1340, in read
    first_packet = self.connection._read_packet()
  File "/Library/Python/2.7/site-packages/pymysql/connections.py", line 1014, in _read_packet
    packet.check_error()
  File "/Library/Python/2.7/site-packages/pymysql/connections.py", line 393, in check_error
    err.raise_mysql_exception(self._data)
  File "/Library/Python/2.7/site-packages/pymysql/err.py", line 107, in raise_mysql_exception
    raise errorclass(errno, errval)
ProgrammingError: (pymysql.err.ProgrammingError) (1146, u"Table 'recmdcstbao.users' doesn't exist") [SQL: u'SELECT users.id AS users_id, users.login AS users_login, users.email AS users_email, users.password AS users_password, users.t AS users_t, users.ut AS users_ut \nFROM users \nWHERE users.login = %(login_1)s \n LIMIT %(param_1)s'] [parameters: {u'login_1': 'fdsf', u'param_1': 1}]
127.0.0.1 - - [30/Jun/2017 23:43:46] "GET /test?__debugger__=yes&cmd=resource&f=style.css HTTP/1.1" 200 -
127.0.0.1 - - [30/Jun/2017 23:43:46] "GET /test?__debugger__=yes&cmd=resource&f=jquery.js HTTP/1.1" 200 -
127.0.0.1 - - [30/Jun/2017 23:43:46] "GET /test?__debugger__=yes&cmd=resource&f=debugger.js HTTP/1.1" 200 -
127.0.0.1 - - [30/Jun/2017 23:43:47] "GET /test?__debugger__=yes&cmd=resource&f=ubuntu.ttf HTTP/1.1" 200 -
127.0.0.1 - - [30/Jun/2017 23:43:47] "GET /test?__debugger__=yes&cmd=resource&f=console.png HTTP/1.1" 200 -
 * Detected change in '/webser/python/recmdcstbao/myapp/models.py', reloading
pbkdf2:sha256:50000$oiU3JNmy$97d6df4f6efd687f136ee0a7dd30c85e8ea14fd80d7c690709800ff52da60870
 * Restarting with stat
 * Debugger is active!
 * Debugger PIN: 198-088-730
 * Detected change in '/webser/python/recmdcstbao/myapp/models.py', reloading
pbkdf2:sha256:50000$PYgYcW0r$50b13ca78132b6c6604a7088efc6ba279a510dd883dc0025bae04ba09a6c0bb1
 * Restarting with stat
 * Debugger is active!
 * Debugger PIN: 198-088-730
 * Detected change in '/webser/python/recmdcstbao/myapp/models.py', reloading
pbkdf2:sha256:50000$0zvTAUDX$eadc97840873f3e6e3cb01cd29550f2ceb182470c455d2e43d746d7db61a3ab3
 * Restarting with stat
 * Debugger is active!
 * Debugger PIN: 198-088-730
 * Detected change in '/webser/python/recmdcstbao/myapp/models.py', reloading
pbkdf2:sha256:50000$AVGZpDAi$f3c85dc542d4d63c127482eee3e7f3c6468c4c5ada8dbc9b42c8563c55ebf829
 * Restarting with stat
 * Debugger is active!
 * Debugger PIN: 198-088-730
127.0.0.1 - - [30/Jun/2017 23:59:19] "GET /test HTTP/1.1" 500 -
Traceback (most recent call last):
  File "/Library/Python/2.7/site-packages/flask/app.py", line 1997, in __call__
    return self.wsgi_app(environ, start_response)
  File "/Library/Python/2.7/site-packages/flask/app.py", line 1985, in wsgi_app
    response = self.handle_exception(e)
  File "/Library/Python/2.7/site-packages/flask/app.py", line 1540, in handle_exception
    reraise(exc_type, exc_value, tb)
  File "/Library/Python/2.7/site-packages/flask/app.py", line 1982, in wsgi_app
    response = self.full_dispatch_request()
  File "/Library/Python/2.7/site-packages/flask/app.py", line 1614, in full_dispatch_request
    rv = self.handle_user_exception(e)
  File "/Library/Python/2.7/site-packages/flask/app.py", line 1517, in handle_user_exception
    reraise(exc_type, exc_value, tb)
  File "/Library/Python/2.7/site-packages/flask/app.py", line 1612, in full_dispatch_request
    rv = self.dispatch_request()
  File "/Library/Python/2.7/site-packages/flask/app.py", line 1598, in dispatch_request
    return self.view_functions[rule.endpoint](**req.view_args)
  File "/webser/python/recmdcstbao/myapp/views/push.py", line 23, in test
    UserModel.query.filter_by(login='fdsf').first()
  File "/Library/Python/2.7/site-packages/sqlalchemy/orm/query.py", line 1562, in filter_by
    for key, value in kwargs.items()]
  File "/Library/Python/2.7/site-packages/sqlalchemy/orm/base.py", line 383, in _entity_descriptor
    (description, key)
InvalidRequestError: Entity '<class 'myapp.models.UserModel'>' has no property 'login'
127.0.0.1 - - [30/Jun/2017 23:59:19] "GET /test?__debugger__=yes&cmd=resource&f=style.css HTTP/1.1" 200 -
127.0.0.1 - - [30/Jun/2017 23:59:19] "GET /test?__debugger__=yes&cmd=resource&f=debugger.js HTTP/1.1" 200 -
127.0.0.1 - - [30/Jun/2017 23:59:19] "GET /test?__debugger__=yes&cmd=resource&f=jquery.js HTTP/1.1" 200 -
127.0.0.1 - - [30/Jun/2017 23:59:19] "GET /test?__debugger__=yes&cmd=resource&f=ubuntu.ttf HTTP/1.1" 200 -
127.0.0.1 - - [30/Jun/2017 23:59:19] "GET /test?__debugger__=yes&cmd=resource&f=console.png HTTP/1.1" 200 -
 * Detected change in '/webser/python/recmdcstbao/myapp/views/push.py', reloading
pbkdf2:sha256:50000$sZ5KmFku$918da9822ea1550d1dfdc9a2c00e806f626fababdc5de3ee97215487f46e899f
 * Restarting with stat
 * Debugger is active!
 * Debugger PIN: 198-088-730
127.0.0.1 - - [30/Jun/2017 23:59:47] "GET /test HTTP/1.1" 200 -
127.0.0.1 - - [01/Jul/2017 00:00:39] "GET /test HTTP/1.1" 200 -
 * Detected change in '/webser/python/recmdcstbao/myapp/views/push.py', reloading
pbkdf2:sha256:50000$Pzhlinhh$1c1cf9b5f802c5dabe6021ad0555f074f41b3ae329bbcec9f35da16f6d8c461a
 * Restarting with stat
 * Debugger is active!
 * Debugger PIN: 198-088-730
127.0.0.1 - - [01/Jul/2017 00:00:54] "GET /test HTTP/1.1" 200 -
 * Detected change in '/webser/python/recmdcstbao/myapp/views/push.py', reloading
pbkdf2:sha256:50000$qKS7MSV5$c9fc0d645d941cff7aab32b6d873eed436d2b1ee596e2096b5449b46c100ad31
 * Restarting with stat
 * Debugger is active!
 * Debugger PIN: 198-088-730
127.0.0.1 - - [01/Jul/2017 00:01:13] "GET /test HTTP/1.1" 500 -
Traceback (most recent call last):
  File "/Library/Python/2.7/site-packages/flask/app.py", line 1997, in __call__
    return self.wsgi_app(environ, start_response)
  File "/Library/Python/2.7/site-packages/flask/app.py", line 1985, in wsgi_app
    response = self.handle_exception(e)
  File "/Library/Python/2.7/site-packages/flask/app.py", line 1540, in handle_exception
    reraise(exc_type, exc_value, tb)
  File "/Library/Python/2.7/site-packages/flask/app.py", line 1982, in wsgi_app
    response = self.full_dispatch_request()
  File "/Library/Python/2.7/site-packages/flask/app.py", line 1615, in full_dispatch_request
    return self.finalize_request(rv)
  File "/Library/Python/2.7/site-packages/flask/app.py", line 1630, in finalize_request
    response = self.make_response(rv)
  File "/Library/Python/2.7/site-packages/flask/app.py", line 1740, in make_response
    rv = self.response_class.force_type(rv, request.environ)
  File "/Library/Python/2.7/site-packages/werkzeug/wrappers.py", line 885, in force_type
    response = BaseResponse(*_run_wsgi_app(response, environ))
  File "/Library/Python/2.7/site-packages/werkzeug/wrappers.py", line 57, in _run_wsgi_app
    return _run_wsgi_app(*args)
  File "/Library/Python/2.7/site-packages/werkzeug/test.py", line 884, in run_wsgi_app
    app_rv = app(environ, start_response)
TypeError: 'UserModel' object is not callable
127.0.0.1 - - [01/Jul/2017 00:01:13] "GET /test?__debugger__=yes&cmd=resource&f=style.css HTTP/1.1" 200 -
127.0.0.1 - - [01/Jul/2017 00:01:13] "GET /test?__debugger__=yes&cmd=resource&f=jquery.js HTTP/1.1" 200 -
127.0.0.1 - - [01/Jul/2017 00:01:13] "GET /test?__debugger__=yes&cmd=resource&f=debugger.js HTTP/1.1" 200 -
127.0.0.1 - - [01/Jul/2017 00:01:13] "GET /test?__debugger__=yes&cmd=resource&f=ubuntu.ttf HTTP/1.1" 200 -
127.0.0.1 - - [01/Jul/2017 00:01:13] "GET /test?__debugger__=yes&cmd=resource&f=console.png HTTP/1.1" 200 -
 * Detected change in '/webser/python/recmdcstbao/myapp/views/push.py', reloading
pbkdf2:sha256:50000$gO3RG1K4$f01cf9184a4604eea1c567eb39598b532fd2ef3467402bea04b9d279095b2cc4
 * Restarting with stat
 * Debugger is active!
 * Debugger PIN: 198-088-730
 * Detected change in '/webser/python/recmdcstbao/myapp/views/push.py', reloading
pbkdf2:sha256:50000$5uf2po7U$8cc9c98b1ea404b6260e52a0b5598de23ee18b6cb727bfb15254b6f292dfe388
 * Restarting with stat
 * Debugger is active!
 * Debugger PIN: 198-088-730
 * Detected change in '/webser/python/recmdcstbao/myapp/views/push.py', reloading
pbkdf2:sha256:50000$m4mY50ir$769cb4c88e1be9b19bcd662fe32d35921fa35649caa8205580668349c3ecc0a9
 * Restarting with stat
 * Debugger is active!
 * Debugger PIN: 198-088-730
Traceback (most recent call last):
  File "/System/Library/Frameworks/Python.framework/Versions/2.7/lib/python2.7/SocketServer.py", line 295, in _handle_request_noblock
    self.process_request(request, client_address)
  File "/System/Library/Frameworks/Python.framework/Versions/2.7/lib/python2.7/SocketServer.py", line 321, in process_request
    self.finish_request(request, client_address)
  File "/System/Library/Frameworks/Python.framework/Versions/2.7/lib/python2.7/SocketServer.py", line 334, in finish_request
    self.RequestHandlerClass(request, client_address, self)
  File "/System/Library/Frameworks/Python.framework/Versions/2.7/lib/python2.7/SocketServer.py", line 655, in __init__
    self.handle()
  File "/Library/Python/2.7/site-packages/werkzeug/serving.py", line 232, in handle
    rv = BaseHTTPRequestHandler.handle(self)
  File "/System/Library/Frameworks/Python.framework/Versions/2.7/lib/python2.7/BaseHTTPServer.py", line 340, in handle
    self.handle_one_request()
  File "/Library/Python/2.7/site-packages/werkzeug/serving.py", line 267, in handle_one_request
    return self.run_wsgi()
  File "/Library/Python/2.7/site-packages/werkzeug/serving.py", line 209, in run_wsgi
    execute(self.server.app)
  File "/Library/Python/2.7/site-packages/werkzeug/serving.py", line 199, in execute
    for data in application_iter:
  File "/Library/Python/2.7/site-packages/werkzeug/debug/__init__.py", line 284, in debug_application
    app_iter = self.app(environ, start_response)
  File "/Library/Python/2.7/site-packages/flask/app.py", line 1997, in __call__
    return self.wsgi_app(environ, start_response)
  File "/Library/Python/2.7/site-packages/flask/app.py", line 1982, in wsgi_app
    response = self.full_dispatch_request()
  File "/Library/Python/2.7/site-packages/flask/app.py", line 1612, in full_dispatch_request
    rv = self.dispatch_request()
  File "/Library/Python/2.7/site-packages/flask/app.py", line 1598, in dispatch_request
    return self.view_functions[rule.endpoint](**req.view_args)
  File "/webser/python/recmdcstbao/myapp/views/push.py", line 24, in test
    exit()
  File "/System/Library/Frameworks/Python.framework/Versions/2.7/lib/python2.7/site.py", line 360, in __call__
    raise SystemExit(code)
SystemExit: None
Traceback (most recent call last):
  File "/System/Library/Frameworks/Python.framework/Versions/2.7/lib/python2.7/SocketServer.py", line 295, in _handle_request_noblock
    self.process_request(request, client_address)
  File "/System/Library/Frameworks/Python.framework/Versions/2.7/lib/python2.7/SocketServer.py", line 321, in process_request
    self.finish_request(request, client_address)
  File "/System/Library/Frameworks/Python.framework/Versions/2.7/lib/python2.7/SocketServer.py", line 334, in finish_request
    self.RequestHandlerClass(request, client_address, self)
  File "/System/Library/Frameworks/Python.framework/Versions/2.7/lib/python2.7/SocketServer.py", line 655, in __init__
    self.handle()
  File "/Library/Python/2.7/site-packages/werkzeug/serving.py", line 232, in handle
    rv = BaseHTTPRequestHandler.handle(self)
  File "/System/Library/Frameworks/Python.framework/Versions/2.7/lib/python2.7/BaseHTTPServer.py", line 340, in handle
    self.handle_one_request()
  File "/Library/Python/2.7/site-packages/werkzeug/serving.py", line 267, in handle_one_request
    return self.run_wsgi()
  File "/Library/Python/2.7/site-packages/werkzeug/serving.py", line 209, in run_wsgi
    execute(self.server.app)
  File "/Library/Python/2.7/site-packages/werkzeug/serving.py", line 199, in execute
    for data in application_iter:
  File "/Library/Python/2.7/site-packages/werkzeug/debug/__init__.py", line 284, in debug_application
    app_iter = self.app(environ, start_response)
  File "/Library/Python/2.7/site-packages/flask/app.py", line 1997, in __call__
    return self.wsgi_app(environ, start_response)
  File "/Library/Python/2.7/site-packages/flask/app.py", line 1982, in wsgi_app
    response = self.full_dispatch_request()
  File "/Library/Python/2.7/site-packages/flask/app.py", line 1612, in full_dispatch_request
    rv = self.dispatch_request()
  File "/Library/Python/2.7/site-packages/flask/app.py", line 1598, in dispatch_request
    return self.view_functions[rule.endpoint](**req.view_args)
  File "/webser/python/recmdcstbao/myapp/views/push.py", line 24, in test
    exit()
  File "/System/Library/Frameworks/Python.framework/Versions/2.7/lib/python2.7/site.py", line 360, in __call__
    raise SystemExit(code)
SystemExit: None
Traceback (most recent call last):
  File "/System/Library/Frameworks/Python.framework/Versions/2.7/lib/python2.7/SocketServer.py", line 295, in _handle_request_noblock
    self.process_request(request, client_address)
  File "/System/Library/Frameworks/Python.framework/Versions/2.7/lib/python2.7/SocketServer.py", line 321, in process_request
    self.finish_request(request, client_address)
  File "/System/Library/Frameworks/Python.framework/Versions/2.7/lib/python2.7/SocketServer.py", line 334, in finish_request
    self.RequestHandlerClass(request, client_address, self)
  File "/System/Library/Frameworks/Python.framework/Versions/2.7/lib/python2.7/SocketServer.py", line 655, in __init__
    self.handle()
  File "/Library/Python/2.7/site-packages/werkzeug/serving.py", line 232, in handle
    rv = BaseHTTPRequestHandler.handle(self)
  File "/System/Library/Frameworks/Python.framework/Versions/2.7/lib/python2.7/BaseHTTPServer.py", line 340, in handle
    self.handle_one_request()
  File "/Library/Python/2.7/site-packages/werkzeug/serving.py", line 267, in handle_one_request
    return self.run_wsgi()
  File "/Library/Python/2.7/site-packages/werkzeug/serving.py", line 209, in run_wsgi
    execute(self.server.app)
  File "/Library/Python/2.7/site-packages/werkzeug/serving.py", line 199, in execute
    for data in application_iter:
  File "/Library/Python/2.7/site-packages/werkzeug/debug/__init__.py", line 284, in debug_application
    app_iter = self.app(environ, start_response)
  File "/Library/Python/2.7/site-packages/flask/app.py", line 1997, in __call__
    return self.wsgi_app(environ, start_response)
  File "/Library/Python/2.7/site-packages/flask/app.py", line 1982, in wsgi_app
    response = self.full_dispatch_request()
  File "/Library/Python/2.7/site-packages/flask/app.py", line 1612, in full_dispatch_request
    rv = self.dispatch_request()
  File "/Library/Python/2.7/site-packages/flask/app.py", line 1598, in dispatch_request
    return self.view_functions[rule.endpoint](**req.view_args)
  File "/webser/python/recmdcstbao/myapp/views/push.py", line 24, in test
    exit()
  File "/System/Library/Frameworks/Python.framework/Versions/2.7/lib/python2.7/site.py", line 360, in __call__
    raise SystemExit(code)
SystemExit: None
Traceback (most recent call last):
  File "/System/Library/Frameworks/Python.framework/Versions/2.7/lib/python2.7/SocketServer.py", line 295, in _handle_request_noblock
    self.process_request(request, client_address)
  File "/System/Library/Frameworks/Python.framework/Versions/2.7/lib/python2.7/SocketServer.py", line 321, in process_request
    self.finish_request(request, client_address)
  File "/System/Library/Frameworks/Python.framework/Versions/2.7/lib/python2.7/SocketServer.py", line 334, in finish_request
    self.RequestHandlerClass(request, client_address, self)
  File "/System/Library/Frameworks/Python.framework/Versions/2.7/lib/python2.7/SocketServer.py", line 655, in __init__
    self.handle()
  File "/Library/Python/2.7/site-packages/werkzeug/serving.py", line 232, in handle
    rv = BaseHTTPRequestHandler.handle(self)
  File "/System/Library/Frameworks/Python.framework/Versions/2.7/lib/python2.7/BaseHTTPServer.py", line 340, in handle
    self.handle_one_request()
  File "/Library/Python/2.7/site-packages/werkzeug/serving.py", line 267, in handle_one_request
    return self.run_wsgi()
  File "/Library/Python/2.7/site-packages/werkzeug/serving.py", line 209, in run_wsgi
    execute(self.server.app)
  File "/Library/Python/2.7/site-packages/werkzeug/serving.py", line 199, in execute
    for data in application_iter:
  File "/Library/Python/2.7/site-packages/werkzeug/debug/__init__.py", line 284, in debug_application
    app_iter = self.app(environ, start_response)
  File "/Library/Python/2.7/site-packages/flask/app.py", line 1997, in __call__
    return self.wsgi_app(environ, start_response)
  File "/Library/Python/2.7/site-packages/flask/app.py", line 1982, in wsgi_app
    response = self.full_dispatch_request()
  File "/Library/Python/2.7/site-packages/flask/app.py", line 1612, in full_dispatch_request
    rv = self.dispatch_request()
  File "/Library/Python/2.7/site-packages/flask/app.py", line 1598, in dispatch_request
    return self.view_functions[rule.endpoint](**req.view_args)
  File "/webser/python/recmdcstbao/myapp/views/push.py", line 24, in test
    exit()
  File "/System/Library/Frameworks/Python.framework/Versions/2.7/lib/python2.7/site.py", line 360, in __call__
    raise SystemExit(code)
SystemExit: None
 * Detected change in '/webser/python/recmdcstbao/myapp/views/push.py', reloading
pbkdf2:sha256:50000$5jgzp5Kx$cac0899252e60e90145adc56fe69ea9bccd954f2f7fbf3ebafca7cdcd3a577bb
----------------------------------------
Exception happened during processing of request from ('127.0.0.1', 53146)
----------------------------------------
----------------------------------------
Exception happened during processing of request from ('127.0.0.1', 53157)
----------------------------------------
----------------------------------------
Exception happened during processing of request from ('127.0.0.1', 53185)
----------------------------------------
----------------------------------------
Exception happened during processing of request from ('127.0.0.1', 53192)
----------------------------------------
 * Restarting with stat
 * Debugger is active!
 * Debugger PIN: 198-088-730
127.0.0.1 - - [01/Jul/2017 00:03:17] "GET /test HTTP/1.1" 200 -
 * Detected change in '/webser/python/recmdcstbao/myapp/views/push.py', reloading
pbkdf2:sha256:50000$vPqlK9h4$32b4addd6ce03b15fe800ebe25598c304feb49030899ce9bc33b175e16b475ac
 * Restarting with stat
 * Debugger is active!
 * Debugger PIN: 198-088-730
127.0.0.1 - - [01/Jul/2017 00:04:27] "GET /test HTTP/1.1" 200 -
 * Detected change in '/webser/python/recmdcstbao/myapp/views/push.py', reloading
pbkdf2:sha256:50000$LXRVjFKC$b1de812f667d5f32e45ee85708a30c4bad98e864c3db4fcc9422af6c190654c2
<User u'18575516501'>
 * Restarting with stat
 * Debugger is active!
 * Debugger PIN: 198-088-730
Traceback (most recent call last):
  File "/System/Library/Frameworks/Python.framework/Versions/2.7/lib/python2.7/SocketServer.py", line 295, in _handle_request_noblock
    self.process_request(request, client_address)
  File "/System/Library/Frameworks/Python.framework/Versions/2.7/lib/python2.7/SocketServer.py", line 321, in process_request
    self.finish_request(request, client_address)
  File "/System/Library/Frameworks/Python.framework/Versions/2.7/lib/python2.7/SocketServer.py", line 334, in finish_request
    self.RequestHandlerClass(request, client_address, self)
  File "/System/Library/Frameworks/Python.framework/Versions/2.7/lib/python2.7/SocketServer.py", line 655, in __init__
    self.handle()
  File "/Library/Python/2.7/site-packages/werkzeug/serving.py", line 232, in handle
    rv = BaseHTTPRequestHandler.handle(self)
  File "/System/Library/Frameworks/Python.framework/Versions/2.7/lib/python2.7/BaseHTTPServer.py", line 340, in handle
    self.handle_one_request()
  File "/Library/Python/2.7/site-packages/werkzeug/serving.py", line 267, in handle_one_request
    return self.run_wsgi()
  File "/Library/Python/2.7/site-packages/werkzeug/serving.py", line 209, in run_wsgi
    execute(self.server.app)
  File "/Library/Python/2.7/site-packages/werkzeug/serving.py", line 199, in execute
    for data in application_iter:
  File "/Library/Python/2.7/site-packages/werkzeug/debug/__init__.py", line 284, in debug_application
    app_iter = self.app(environ, start_response)
  File "/Library/Python/2.7/site-packages/flask/app.py", line 1997, in __call__
    return self.wsgi_app(environ, start_response)
  File "/Library/Python/2.7/site-packages/flask/app.py", line 1982, in wsgi_app
    response = self.full_dispatch_request()
  File "/Library/Python/2.7/site-packages/flask/app.py", line 1612, in full_dispatch_request
    rv = self.dispatch_request()
  File "/Library/Python/2.7/site-packages/flask/app.py", line 1598, in dispatch_request
    return self.view_functions[rule.endpoint](**req.view_args)
  File "/webser/python/recmdcstbao/myapp/views/push.py", line 25, in test
    quit()
  File "/System/Library/Frameworks/Python.framework/Versions/2.7/lib/python2.7/site.py", line 360, in __call__
    raise SystemExit(code)
SystemExit: None
Traceback (most recent call last):
  File "/System/Library/Frameworks/Python.framework/Versions/2.7/lib/python2.7/SocketServer.py", line 295, in _handle_request_noblock
    self.process_request(request, client_address)
  File "/System/Library/Frameworks/Python.framework/Versions/2.7/lib/python2.7/SocketServer.py", line 321, in process_request
    self.finish_request(request, client_address)
  File "/System/Library/Frameworks/Python.framework/Versions/2.7/lib/python2.7/SocketServer.py", line 334, in finish_request
    self.RequestHandlerClass(request, client_address, self)
  File "/System/Library/Frameworks/Python.framework/Versions/2.7/lib/python2.7/SocketServer.py", line 655, in __init__
    self.handle()
  File "/Library/Python/2.7/site-packages/werkzeug/serving.py", line 232, in handle
    rv = BaseHTTPRequestHandler.handle(self)
  File "/System/Library/Frameworks/Python.framework/Versions/2.7/lib/python2.7/BaseHTTPServer.py", line 340, in handle
    self.handle_one_request()
  File "/Library/Python/2.7/site-packages/werkzeug/serving.py", line 267, in handle_one_request
    return self.run_wsgi()
  File "/Library/Python/2.7/site-packages/werkzeug/serving.py", line 209, in run_wsgi
    execute(self.server.app)
  File "/Library/Python/2.7/site-packages/werkzeug/serving.py", line 199, in execute
    for data in application_iter:
  File "/Library/Python/2.7/site-packages/werkzeug/debug/__init__.py", line 284, in debug_application
    app_iter = self.app(environ, start_response)
  File "/Library/Python/2.7/site-packages/flask/app.py", line 1997, in __call__
    return self.wsgi_app(environ, start_response)
  File "/Library/Python/2.7/site-packages/flask/app.py", line 1982, in wsgi_app
    response = self.full_dispatch_request()
  File "/Library/Python/2.7/site-packages/flask/app.py", line 1612, in full_dispatch_request
    rv = self.dispatch_request()
  File "/Library/Python/2.7/site-packages/flask/app.py", line 1598, in dispatch_request
    return self.view_functions[rule.endpoint](**req.view_args)
  File "/webser/python/recmdcstbao/myapp/views/push.py", line 25, in test
    quit()
  File "/System/Library/Frameworks/Python.framework/Versions/2.7/lib/python2.7/site.py", line 360, in __call__
    raise SystemExit(code)
SystemExit: None
Traceback (most recent call last):
  File "/System/Library/Frameworks/Python.framework/Versions/2.7/lib/python2.7/SocketServer.py", line 295, in _handle_request_noblock
    self.process_request(request, client_address)
  File "/System/Library/Frameworks/Python.framework/Versions/2.7/lib/python2.7/SocketServer.py", line 321, in process_request
    self.finish_request(request, client_address)
  File "/System/Library/Frameworks/Python.framework/Versions/2.7/lib/python2.7/SocketServer.py", line 334, in finish_request
    self.RequestHandlerClass(request, client_address, self)
  File "/System/Library/Frameworks/Python.framework/Versions/2.7/lib/python2.7/SocketServer.py", line 655, in __init__
    self.handle()
  File "/Library/Python/2.7/site-packages/werkzeug/serving.py", line 232, in handle
    rv = BaseHTTPRequestHandler.handle(self)
  File "/System/Library/Frameworks/Python.framework/Versions/2.7/lib/python2.7/BaseHTTPServer.py", line 340, in handle
    self.handle_one_request()
  File "/Library/Python/2.7/site-packages/werkzeug/serving.py", line 267, in handle_one_request
    return self.run_wsgi()
  File "/Library/Python/2.7/site-packages/werkzeug/serving.py", line 209, in run_wsgi
    execute(self.server.app)
  File "/Library/Python/2.7/site-packages/werkzeug/serving.py", line 199, in execute
    for data in application_iter:
  File "/Library/Python/2.7/site-packages/werkzeug/debug/__init__.py", line 284, in debug_application
    app_iter = self.app(environ, start_response)
  File "/Library/Python/2.7/site-packages/flask/app.py", line 1997, in __call__
    return self.wsgi_app(environ, start_response)
  File "/Library/Python/2.7/site-packages/flask/app.py", line 1982, in wsgi_app
    response = self.full_dispatch_request()
  File "/Library/Python/2.7/site-packages/flask/app.py", line 1612, in full_dispatch_request
    rv = self.dispatch_request()
  File "/Library/Python/2.7/site-packages/flask/app.py", line 1598, in dispatch_request
    return self.view_functions[rule.endpoint](**req.view_args)
  File "/webser/python/recmdcstbao/myapp/views/push.py", line 25, in test
    quit()
  File "/System/Library/Frameworks/Python.framework/Versions/2.7/lib/python2.7/site.py", line 360, in __call__
    raise SystemExit(code)
SystemExit: None
 * Detected change in '/webser/python/recmdcstbao/myapp/views/push.py', reloading
pbkdf2:sha256:50000$jtesHtIT$e8857487c3a2c4bfb3bb30e7ef9dd3294d27bfadb0011334075aa7af5d70576f
<User u'18575516501'>
----------------------------------------
Exception happened during processing of request from ('127.0.0.1', 53832)
----------------------------------------
<User u'18575516501'>
----------------------------------------
Exception happened during processing of request from ('127.0.0.1', 53835)
----------------------------------------
<User u'18575516501'>
----------------------------------------
Exception happened during processing of request from ('127.0.0.1', 53857)
----------------------------------------
 * Restarting with stat
 * Debugger is active!
 * Debugger PIN: 198-088-730
 * Detected change in '/webser/python/recmdcstbao/myapp/views/push.py', reloading
pbkdf2:sha256:50000$MGL76q2v$da3ded7f1f2466f95e0ca0e4af755c3a55cf1bf545a911b10f72ba445f537848
 * Restarting with stat
 * Debugger is active!
 * Debugger PIN: 198-088-730
Traceback (most recent call last):
  File "/System/Library/Frameworks/Python.framework/Versions/2.7/lib/python2.7/SocketServer.py", line 295, in _handle_request_noblock
    self.process_request(request, client_address)
  File "/System/Library/Frameworks/Python.framework/Versions/2.7/lib/python2.7/SocketServer.py", line 321, in process_request
    self.finish_request(request, client_address)
  File "/System/Library/Frameworks/Python.framework/Versions/2.7/lib/python2.7/SocketServer.py", line 334, in finish_request
    self.RequestHandlerClass(request, client_address, self)
  File "/System/Library/Frameworks/Python.framework/Versions/2.7/lib/python2.7/SocketServer.py", line 655, in __init__
    self.handle()
  File "/Library/Python/2.7/site-packages/werkzeug/serving.py", line 232, in handle
    rv = BaseHTTPRequestHandler.handle(self)
  File "/System/Library/Frameworks/Python.framework/Versions/2.7/lib/python2.7/BaseHTTPServer.py", line 340, in handle
    self.handle_one_request()
  File "/Library/Python/2.7/site-packages/werkzeug/serving.py", line 267, in handle_one_request
    return self.run_wsgi()
  File "/Library/Python/2.7/site-packages/werkzeug/serving.py", line 209, in run_wsgi
    execute(self.server.app)
  File "/Library/Python/2.7/site-packages/werkzeug/serving.py", line 199, in execute
    for data in application_iter:
  File "/Library/Python/2.7/site-packages/werkzeug/debug/__init__.py", line 284, in debug_application
    app_iter = self.app(environ, start_response)
  File "/Library/Python/2.7/site-packages/flask/app.py", line 1997, in __call__
    return self.wsgi_app(environ, start_response)
  File "/Library/Python/2.7/site-packages/flask/app.py", line 1982, in wsgi_app
    response = self.full_dispatch_request()
  File "/Library/Python/2.7/site-packages/flask/app.py", line 1612, in full_dispatch_request
    rv = self.dispatch_request()
  File "/Library/Python/2.7/site-packages/flask/app.py", line 1598, in dispatch_request
    return self.view_functions[rule.endpoint](**req.view_args)
  File "/webser/python/recmdcstbao/myapp/views/push.py", line 25, in test
    exit()
  File "/System/Library/Frameworks/Python.framework/Versions/2.7/lib/python2.7/site.py", line 360, in __call__
    raise SystemExit(code)
SystemExit: None
 * Detected change in '/webser/python/recmdcstbao/myapp/views/push.py', reloading
pbkdf2:sha256:50000$uoOcPiAo$20f32c92b60cb498c842f027e6a01726a4bec27083c4899ca747365c9157755e
<User u'18575516501'>
----------------------------------------
Exception happened during processing of request from ('127.0.0.1', 53923)
----------------------------------------
 * Restarting with stat
 * Debugger is active!
 * Debugger PIN: 198-088-730
127.0.0.1 - - [01/Jul/2017 00:05:51] "GET /test HTTP/1.1" 200 -
 * Detected change in '/webser/python/recmdcstbao/myapp/views/push.py', reloading
pbkdf2:sha256:50000$32mTrmHM$a693da881580e597f0714dd7fca4184af4f0dcf599c3517148e8172a5fd85cdd
<User u'18575516501'>
 * Restarting with stat
 * Debugger is active!
 * Debugger PIN: 198-088-730
127.0.0.1 - - [01/Jul/2017 00:06:16] "GET /test HTTP/1.1" 200 -
 * Detected change in '/webser/python/recmdcstbao/myapp/views/push.py', reloading
pbkdf2:sha256:50000$kHL4fJmF$a1bbef36cd02c1b9cf5172d6b2802da67ae8529845dab0cba6dfeb98dd5cc1de
 * Restarting with stat
 * Debugger is active!
 * Debugger PIN: 198-088-730
 * Detected change in '/webser/python/recmdcstbao/myapp/views/push.py', reloading
pbkdf2:sha256:50000$sWOPUfWU$8478670d01b8361ac7a7cbc955f2e06533b1f1b77df84f6e048f7e77a11363e9
 * Restarting with stat
 * Debugger is active!
 * Debugger PIN: 198-088-730
127.0.0.1 - - [01/Jul/2017 00:06:36] "GET /test HTTP/1.1" 200 -
 * Detected change in '/webser/python/recmdcstbao/myapp/models.py', reloading
pbkdf2:sha256:50000$8HNsUtw8$20979b15dcd2cdade764493c08856a5904c7a684bda6a06124cea6e86862c22b
 * Restarting with stat
 * Debugger is active!
 * Debugger PIN: 198-088-730
 * Detected change in '/webser/python/recmdcstbao/myapp/models.py', reloading
pbkdf2:sha256:50000$hLBhX4mG$157ad7dc763430d92af7e049b6cd686e8be2826efc6871aa0771a878cddb3a17
 * Restarting with stat
 * Debugger is active!
 * Debugger PIN: 198-088-730
 * Detected change in '/webser/python/recmdcstbao/myapp/models.py', reloading
pbkdf2:sha256:50000$6BIEZiG6$03593b121828fea7eb1d9feaa60ecbab6c086327ebef4ee6d6add22101406a82
 * Restarting with stat
 * Debugger is active!
 * Debugger PIN: 198-088-730
 * Detected change in '/webser/python/recmdcstbao/myapp/models.py', reloading
pbkdf2:sha256:50000$9qeE2CRS$fcf27c6348d95f7e1c92ec9d461e7ab5d10afc1fe2d9f32e44aed0fa8d642863
 * Restarting with stat
 * Debugger is active!
 * Debugger PIN: 198-088-730
 * Detected change in '/webser/python/recmdcstbao/myapp/models.py', reloading
pbkdf2:sha256:50000$SW2P3wZ8$12baac83ae2813ef840ac422610099fe576e93605a1e0619513cce1ee79de55f
 * Restarting with stat
 * Debugger is active!
 * Debugger PIN: 198-088-730
 * Detected change in '/webser/python/recmdcstbao/myapp/models.py', reloading
pbkdf2:sha256:50000$txsP2wOj$610964ce17a143547c95393fa109f82456ab810bdb91385dea969cc60570cf04
 * Restarting with stat
 * Debugger is active!
 * Debugger PIN: 198-088-730
 * Detected change in '/webser/python/recmdcstbao/myapp/models.py', reloading
pbkdf2:sha256:50000$4D8arsdW$c874483db21c2d113d71e5c6b4491978addcd5b8bbba2c59a3c8075e67d3894c
 * Restarting with stat
 * Debugger is active!
 * Debugger PIN: 198-088-730
127.0.0.1 - - [01/Jul/2017 11:11:35] "GET /test HTTP/1.0" 200 -
127.0.0.1 - - [01/Jul/2017 11:11:35] "GET /favicon.ico HTTP/1.0" 404 -
 * Detected change in '/webser/python/recmdcstbao/myapp/views/push.py', reloading
pbkdf2:sha256:50000$SMLSzaMx$f174aba97af1813e58f99ebd578389ad6c41afff429b9d57d9b1a1660780c03b
 * Restarting with stat
 * Debugger is active!
 * Debugger PIN: 198-088-730
 * Detected change in '/webser/python/recmdcstbao/myapp/views/push.py', reloading
pbkdf2:sha256:50000$lLpxmyMF$f3e76ec52371888f8a460c573678730dd56d196ffb69c41223710860bae0c7b1
 * Restarting with stat
 * Debugger is active!
 * Debugger PIN: 198-088-730
127.0.0.1 - - [01/Jul/2017 11:12:54] "GET /api HTTP/1.0" 200 -
127.0.0.1 - - [01/Jul/2017 11:12:56] "GET /api HTTP/1.0" 200 -
 * Detected change in '/webser/python/recmdcstbao/myapp/models.py', reloading
pbkdf2:sha256:50000$1od34zWx$72a8ba9de092fe12d0d4af017188142ee9a55012ac7f6215e892072509d5bc2c
 * Restarting with stat
 * Debugger is active!
 * Debugger PIN: 198-088-730
 * Detected change in '/webser/python/recmdcstbao/myapp/models.py', reloading
pbkdf2:sha256:50000$nJ2Db8nH$b7fe099ab3917864ee34153faac1bd0f1c52e2331f7f929a29b60f6a9f1eaabb
 * Restarting with stat
 * Debugger is active!
 * Debugger PIN: 198-088-730
127.0.0.1 - - [01/Jul/2017 11:23:57] "GET /api/customer/save HTTP/1.0" 404 -
127.0.0.1 - - [01/Jul/2017 11:25:23] "GET /api/customer/save HTTP/1.0" 404 -
127.0.0.1 - - [01/Jul/2017 11:25:49] "GET /api/customer/save HTTP/1.0" 404 -
127.0.0.1 - - [01/Jul/2017 11:27:45] "GET /api/customer/save HTTP/1.0" 404 -
127.0.0.1 - - [01/Jul/2017 11:37:48] "GET /api/customer/save HTTP/1.0" 404 -
 * Detected change in '/webser/python/recmdcstbao/myapp/views/__init__.py', reloading
pbkdf2:sha256:50000$dVIMGz4C$d733c8beb9a485291ac575753a70f660a89addc331d96805c4f34a402988365b
 * Restarting with stat
 * Debugger is active!
 * Debugger PIN: 198-088-730
127.0.0.1 - - [01/Jul/2017 11:38:04] "GET /api/customer/save HTTP/1.0" 200 -
 * Detected change in '/webser/python/recmdcstbao/myapp/views/front.py', reloading
pbkdf2:sha256:50000$dZjXYOHy$6cab2492fcc1965f0a57e738a0f1794f031f542370b7c2dc224f2685b2a96c0e
 * Restarting with stat
 * Debugger is active!
 * Debugger PIN: 198-088-730
127.0.0.1 - - [01/Jul/2017 11:40:16] "GET /api/customer/save HTTP/1.0" 405 -
127.0.0.1 - - [01/Jul/2017 11:41:32] "GET /test HTTP/1.0" 404 -
127.0.0.1 - - [01/Jul/2017 11:41:33] "GET /favicon.ico HTTP/1.0" 404 -
127.0.0.1 - - [01/Jul/2017 11:41:39] "GET /test HTTP/1.0" 404 -
127.0.0.1 - - [01/Jul/2017 11:41:47] "GET /api HTTP/1.0" 200 -
127.0.0.1 - - [01/Jul/2017 11:42:54] "POST /api/customer/save HTTP/1.0" 200 -
 * Detected change in '/webser/python/recmdcstbao/myapp/views/front.py', reloading
pbkdf2:sha256:50000$WHdGvb3c$7013c98cf739804df26a42ad2d9defc28bffda19d49d82ecac0f5051fb269609
 * Restarting with stat
 * Debugger is active!
 * Debugger PIN: 198-088-730
 * Detected change in '/webser/python/recmdcstbao/myapp/views/front.py', reloading
pbkdf2:sha256:50000$3Hplr5Hl$f6714d70f72afc9156482ff80ecbda0f046bc42b40cfad569eabf48e0f0a965f
 * Restarting with stat
Traceback (most recent call last):
  File "index.py", line 6, in <module>
    from myapp import app
  File "/webser/python/recmdcstbao/myapp/__init__.py", line 15, in <module>
    from views import *
  File "/webser/python/recmdcstbao/myapp/views/__init__.py", line 5, in <module>
    from front import *
  File "/webser/python/recmdcstbao/myapp/views/front.py", line 11
    request.
           ^
SyntaxError: invalid syntax
pbkdf2:sha256:50000$ih377Zpj$2aaf3baf1cec0e14671b7059fe864ab4b40c85c168c53c382037d474ec50f4a5
 * Running on http://0.0.0.0:5000/ (Press CTRL+C to quit)
 * Restarting with stat
 * Debugger is active!
 * Debugger PIN: 198-088-730
127.0.0.1 - - [01/Jul/2017 11:48:25] "POST /api/customer/save HTTP/1.0" 200 -
127.0.0.1 - - [01/Jul/2017 11:48:37] "GET /api/customer/save HTTP/1.0" 405 -
 * Detected change in '/webser/python/recmdcstbao/myapp/views/front.py', reloading
pbkdf2:sha256:50000$NLTC9ldO$34314145478492c3c72575d2dc570b31d44149f662839eea2bef3fc09fb90754
 * Restarting with stat
 * Debugger is active!
 * Debugger PIN: 198-088-730
127.0.0.1 - - [01/Jul/2017 11:49:44] "POST /api/customer/save HTTP/1.0" 200 -
 * Detected change in '/webser/python/recmdcstbao/myapp/views/front.py', reloading
pbkdf2:sha256:50000$VMpRDPuP$2c0fed1c5eb639604a65bcf07609ad32818a9eda47a055bc0ac36e7215ed9c36
 * Restarting with stat
 * Debugger is active!
 * Debugger PIN: 198-088-730
 * Detected change in '/webser/python/recmdcstbao/myapp/views/front.py', reloading
pbkdf2:sha256:50000$2Qwe8xzS$e5fefe7d2a46bd98a06e0271287a2674ad766463686bcee0f380e9987ce45037
 * Restarting with stat
 * Debugger is active!
 * Debugger PIN: 198-088-730
 * Detected change in '/webser/python/recmdcstbao/myapp/views/front.py', reloading
pbkdf2:sha256:50000$PmSqbvBV$638a2424024b2ffc606747b91bc6f0ae757755b7a2142ebacd7c7797c97ca08f
 * Restarting with stat
 * Debugger is active!
 * Debugger PIN: 198-088-730
127.0.0.1 - - [01/Jul/2017 11:51:18] "POST /api/customer/save HTTP/1.0" 200 -
 * Detected change in '/webser/python/recmdcstbao/myapp/models.py', reloading
pbkdf2:sha256:50000$znQPjSDo$4ea8ee79c983f9e9491e609001b61129a562b1680b68a3849f2e8b1722018479
 * Restarting with stat
 * Debugger is active!
 * Debugger PIN: 198-088-730
 * Detected change in '/webser/python/recmdcstbao/myapp/models.py', reloading
pbkdf2:sha256:50000$iV80G8v9$35101b5eeaca2cab887fd2c1038c3b6544b97605f4c8729e8c90b76f49609803
 * Restarting with stat
Traceback (most recent call last):
  File "index.py", line 6, in <module>
    from myapp import app
  File "/webser/python/recmdcstbao/myapp/__init__.py", line 14, in <module>
    from models import UserModel
  File "/webser/python/recmdcstbao/myapp/models.py", line 46
    
    ^
IndentationError: expected an indented block
pbkdf2:sha256:50000$xjA9kiKY$5f1c3e276d51d346c57076786d31d17b67fe53ef046017140238c965342dedf0
 * Running on http://0.0.0.0:5000/ (Press CTRL+C to quit)
 * Restarting with stat
 * Debugger is active!
 * Debugger PIN: 198-088-730
/Library/Python/2.7/site-packages/sqlalchemy/sql/compiler.py:624: SAWarning: Can't resolve label reference 'created_time desc'; converting to text() (this warning may be suppressed after 10 occurrences)
  util.ellipses_string(element.element))
127.0.0.1 - - [01/Jul/2017 15:33:47] "GET /api/company/list HTTP/1.0" 200 -
127.0.0.1 - - [01/Jul/2017 15:35:11] "GET /api/company/list HTTP/1.0" 200 -
127.0.0.1 - - [01/Jul/2017 15:36:13] "GET /api/company/list HTTP/1.0" 200 -
127.0.0.1 - - [01/Jul/2017 15:36:23] "GET /api/company/list HTTP/1.0" 200 -
127.0.0.1 - - [01/Jul/2017 15:36:38] "GET /api/company/list HTTP/1.0" 200 -
127.0.0.1 - - [01/Jul/2017 15:39:20] "GET /api/company/list HTTP/1.0" 200 -
 * Detected change in '/webser/python/recmdcstbao/myapp/views/customer.py', reloading
pbkdf2:sha256:50000$DdcOhP0z$245d2c07f2c9a7783c480392f5df9693138c403b947a1b9928251192583f0087
 * Restarting with stat
 * Debugger is active!
 * Debugger PIN: 198-088-730
/Library/Python/2.7/site-packages/sqlalchemy/sql/compiler.py:624: SAWarning: Can't resolve label reference 'created_time desc'; converting to text() (this warning may be suppressed after 10 occurrences)
  util.ellipses_string(element.element))
127.0.0.1 - - [01/Jul/2017 15:40:00] "GET /api/company/list HTTP/1.0" 200 -
127.0.0.1 - - [01/Jul/2017 15:41:39] "GET /api/company/list HTTP/1.0" 200 -
 * Detected change in '/webser/python/recmdcstbao/myapp/views/customer.py', reloading
pbkdf2:sha256:50000$1FDAPZGP$4f3a22e6400b2d19de430b28083847fdb1e3f20b9c87e9182d01a5eca380a4aa
 * Restarting with stat
 * Debugger is active!
 * Debugger PIN: 198-088-730
/Library/Python/2.7/site-packages/sqlalchemy/sql/compiler.py:624: SAWarning: Can't resolve label reference 'created_time desc'; converting to text() (this warning may be suppressed after 10 occurrences)
  util.ellipses_string(element.element))
127.0.0.1 - - [01/Jul/2017 15:41:59] "GET /api/company/list HTTP/1.0" 200 -
127.0.0.1 - - [01/Jul/2017 15:41:59] "POST /api/customer/save HTTP/1.0" 200 -
127.0.0.1 - - [01/Jul/2017 15:42:05] "POST /api/customer/save HTTP/1.0" 200 -
127.0.0.1 - - [01/Jul/2017 15:44:00] "GET /api/company/list HTTP/1.0" 200 -
127.0.0.1 - - [01/Jul/2017 15:45:38] "POST /api/customer/save HTTP/1.0" 200 -
127.0.0.1 - - [01/Jul/2017 15:48:11] "GET /api/customer/list HTTP/1.0" 200 -
127.0.0.1 - - [01/Jul/2017 15:48:27] "GET /api/customer/1 HTTP/1.0" 404 -
127.0.0.1 - - [01/Jul/2017 15:49:53] "GET /api/company/list HTTP/1.0" 200 -
127.0.0.1 - - [01/Jul/2017 15:50:00] "GET /api/company/list HTTP/1.0" 200 -
127.0.0.1 - - [01/Jul/2017 15:50:07] "GET /api/company/list HTTP/1.0" 200 -
127.0.0.1 - - [01/Jul/2017 15:50:21] "GET /api/customer/2 HTTP/1.0" 404 -
127.0.0.1 - - [01/Jul/2017 15:50:32] "GET /api/customer/list HTTP/1.0" 200 -
127.0.0.1 - - [01/Jul/2017 15:51:58] "GET /api/company/list HTTP/1.0" 200 -
 * Detected change in '/webser/python/recmdcstbao/myapp/models.py', reloading
pbkdf2:sha256:50000$mMm09LNh$5dee248c9c8fe441be50879163a9dcaa735cd1657ab0770bd962573e8b333f9e
 * Restarting with stat
 * Debugger is active!
 * Debugger PIN: 198-088-730
/Library/Python/2.7/site-packages/sqlalchemy/sql/compiler.py:624: SAWarning: Can't resolve label reference 'created_time desc'; converting to text() (this warning may be suppressed after 10 occurrences)
  util.ellipses_string(element.element))
127.0.0.1 - - [01/Jul/2017 15:52:39] "GET /api/company/list HTTP/1.0" 200 -
127.0.0.1 - - [01/Jul/2017 15:52:55] "GET /api/company/list HTTP/1.0" 200 -
127.0.0.1 - - [01/Jul/2017 15:53:02] "GET /api/company/list HTTP/1.0" 200 -
127.0.0.1 - - [01/Jul/2017 15:53:10] "GET /api/company/list HTTP/1.0" 200 -
127.0.0.1 - - [01/Jul/2017 15:53:11] "GET /favicon.ico HTTP/1.0" 404 -
127.0.0.1 - - [01/Jul/2017 15:53:22] "GET /api/company/list HTTP/1.0" 200 -
127.0.0.1 - - [01/Jul/2017 15:53:43] "GET /api/company/list HTTP/1.0" 200 -
127.0.0.1 - - [01/Jul/2017 15:53:53] "GET /api/company/list HTTP/1.0" 200 -
127.0.0.1 - - [01/Jul/2017 15:54:55] "GET /api/customer/1 HTTP/1.0" 404 -
127.0.0.1 - - [01/Jul/2017 15:55:08] "GET /api/customer/get/1 HTTP/1.0" 404 -
127.0.0.1 - - [01/Jul/2017 15:55:12] "GET /api/customer/1 HTTP/1.0" 404 -
127.0.0.1 - - [01/Jul/2017 15:55:59] "GET /api/customer/1 HTTP/1.0" 404 -
 * Detected change in '/webser/python/recmdcstbao/myapp/views/customer.py', reloading
pbkdf2:sha256:50000$wjwnLvIr$0709940dfb009e786517a0ec284ceea7a48b0b0484385ccd47b9b0143bb62fe4
 * Restarting with stat
 * Debugger is active!
 * Debugger PIN: 198-088-730
127.0.0.1 - - [01/Jul/2017 15:56:13] "GET /api/customer/1 HTTP/1.0" 200 -
127.0.0.1 - - [01/Jul/2017 15:56:13] "GET /api/customer/1 HTTP/1.0" 200 -
127.0.0.1 - - [01/Jul/2017 15:56:15] "GET /api/customer/1 HTTP/1.0" 200 -
/Library/Python/2.7/site-packages/sqlalchemy/sql/compiler.py:624: SAWarning: Can't resolve label reference 'created_time desc'; converting to text() (this warning may be suppressed after 10 occurrences)
  util.ellipses_string(element.element))
127.0.0.1 - - [01/Jul/2017 15:56:35] "GET /api/company/list HTTP/1.0" 200 -
127.0.0.1 - - [01/Jul/2017 15:56:36] "GET /xxx HTTP/1.0" 404 -
127.0.0.1 - - [01/Jul/2017 15:58:23] "GET /api/company/list HTTP/1.0" 200 -
127.0.0.1 - - [01/Jul/2017 15:58:24] "GET /xxx HTTP/1.0" 404 -
127.0.0.1 - - [01/Jul/2017 15:58:26] "GET /api/company/list HTTP/1.0" 200 -
127.0.0.1 - - [01/Jul/2017 15:58:26] "GET /xxx HTTP/1.0" 404 -
127.0.0.1 - - [01/Jul/2017 15:58:42] "GET /xxx HTTP/1.0" 404 -
127.0.0.1 - - [01/Jul/2017 16:08:30] "GET /xxx HTTP/1.0" 404 -
127.0.0.1 - - [01/Jul/2017 16:08:34] "GET /api/company/list HTTP/1.0" 200 -
127.0.0.1 - - [01/Jul/2017 16:08:34] "GET /xxx HTTP/1.0" 404 -
127.0.0.1 - - [01/Jul/2017 16:12:46] "GET /api/company/list HTTP/1.0" 200 -
127.0.0.1 - - [01/Jul/2017 16:31:52] "GET /api/company/list HTTP/1.0" 200 -
127.0.0.1 - - [01/Jul/2017 16:32:46] "GET /api/company/list HTTP/1.0" 200 -
127.0.0.1 - - [01/Jul/2017 16:33:50] "GET /api/company/list HTTP/1.0" 200 -
127.0.0.1 - - [01/Jul/2017 16:33:50] "GET /api/company/list HTTP/1.0" 200 -
127.0.0.1 - - [01/Jul/2017 16:35:35] "GET /api/company/list HTTP/1.0" 200 -
127.0.0.1 - - [01/Jul/2017 16:37:05] "GET /api/company/list HTTP/1.0" 200 -
127.0.0.1 - - [01/Jul/2017 16:38:47] "GET /api/company/list HTTP/1.0" 200 -
127.0.0.1 - - [01/Jul/2017 16:39:32] "GET /api/company/list HTTP/1.0" 200 -
127.0.0.1 - - [01/Jul/2017 16:39:43] "GET /api/company/list HTTP/1.0" 200 -
 * Detected change in '/webser/python/recmdcstbao/myapp/models.py', reloading
pbkdf2:sha256:50000$x6Ga9qTh$5f55f24be514c1a8e9206bf6a666bfdde06bd18b9ffe2a907376fdb1ec8a5be5
 * Restarting with stat
 * Debugger is active!
 * Debugger PIN: 198-088-730
/Library/Python/2.7/site-packages/sqlalchemy/sql/compiler.py:624: SAWarning: Can't resolve label reference 'created_time desc'; converting to text() (this warning may be suppressed after 10 occurrences)
  util.ellipses_string(element.element))
127.0.0.1 - - [01/Jul/2017 16:40:34] "GET /api/company/list HTTP/1.0" 200 -
127.0.0.1 - - [01/Jul/2017 16:40:35] "GET /api/company/list HTTP/1.0" 200 -
127.0.0.1 - - [01/Jul/2017 16:40:41] "GET /api/company/list HTTP/1.0" 200 -
127.0.0.1 - - [01/Jul/2017 16:40:42] "GET /api/company/list HTTP/1.0" 200 -
 * Detected change in '/webser/python/recmdcstbao/myapp/models.py', reloading
pbkdf2:sha256:50000$NC2hsDSH$64a185eb7e97d66e7a30fb3594be0ba7e26ca95e98ccc2bd6d40165676f3a23b
Exception in thread Thread-1 (most likely raised during interpreter shutdown):
Traceback (most recent call last):
  File "/System/Library/Frameworks/Python.framework/Versions/2.7/lib/python2.7/threading.py", line 810, in __bootstrap_inner
  File "/System/Library/Frameworks/Python.framework/Versions/2.7/lib/python2.7/threading.py", line 763, in run
  File "/Library/Python/2.7/site-packages/werkzeug/serving.py", line 702, in inner
  File "/Library/Python/2.7/site-packages/werkzeug/serving.py", line 539, in serve_forever
  File "/System/Library/Frameworks/Python.framework/Versions/2.7/lib/python2.7/SocketServer.py", line 241, in serve_forever
  File "/System/Library/Frameworks/Python.framework/Versions/2.7/lib/python2.7/threading.py", line 586, in set
  File "/System/Library/Frameworks/Python.framework/Versions/2.7/lib/python2.7/threading.py", line 407, in notifyAll
<type 'exceptions.TypeError'>: 'NoneType' object is not callable
 * Restarting with stat
 * Debugger is active!
 * Debugger PIN: 198-088-730
/Library/Python/2.7/site-packages/sqlalchemy/sql/compiler.py:624: SAWarning: Can't resolve label reference 'created_time desc'; converting to text() (this warning may be suppressed after 10 occurrences)
  util.ellipses_string(element.element))
127.0.0.1 - - [01/Jul/2017 16:40:57] "GET /api/company/list HTTP/1.0" 200 -
127.0.0.1 - - [01/Jul/2017 16:40:57] "GET /api/company/list HTTP/1.0" 200 -
 * Detected change in '/webser/python/recmdcstbao/myapp/models.py', reloading
pbkdf2:sha256:50000$b46VWqsR$15890ec8c01d05b15713a01875918870979981078ee1f095e7322fed51052de0
 * Restarting with stat
 * Debugger is active!
 * Debugger PIN: 198-088-730
/Library/Python/2.7/site-packages/sqlalchemy/sql/compiler.py:624: SAWarning: Can't resolve label reference 'created_time desc'; converting to text() (this warning may be suppressed after 10 occurrences)
  util.ellipses_string(element.element))
127.0.0.1 - - [01/Jul/2017 16:41:13] "GET /api/company/list HTTP/1.0" 200 -
127.0.0.1 - - [01/Jul/2017 16:41:13] "GET /api/company/list HTTP/1.0" 200 -
127.0.0.1 - - [01/Jul/2017 16:41:49] "GET /api/company/list HTTP/1.0" 200 -
127.0.0.1 - - [01/Jul/2017 16:41:50] "GET /api/company/list HTTP/1.0" 200 -
 * Detected change in '/webser/python/recmdcstbao/myapp/models.py', reloading
pbkdf2:sha256:50000$MP85l2JS$9e6c5692902d15d792a55ce2e5209ed3176808605e95f97ab84e8329a2c0a012
 * Restarting with stat
 * Debugger is active!
 * Debugger PIN: 198-088-730
/Library/Python/2.7/site-packages/sqlalchemy/sql/compiler.py:624: SAWarning: Can't resolve label reference 'created_time desc'; converting to text() (this warning may be suppressed after 10 occurrences)
  util.ellipses_string(element.element))
127.0.0.1 - - [01/Jul/2017 16:43:44] "GET /api/company/list HTTP/1.0" 200 -
127.0.0.1 - - [01/Jul/2017 16:43:44] "GET /api/company/list HTTP/1.0" 200 -
127.0.0.1 - - [01/Jul/2017 16:44:00] "GET /api/company/list HTTP/1.0" 200 -
127.0.0.1 - - [01/Jul/2017 16:44:00] "GET /api/company/list HTTP/1.0" 200 -
 * Detected change in '/webser/python/recmdcstbao/myapp/models.py', reloading
pbkdf2:sha256:50000$YrsgTsK6$b6ee75712a1f29fc9b90bd93cdba673e84ffb3f5203ed3641ea4c947ef32d569
 * Restarting with stat
 * Debugger is active!
 * Debugger PIN: 198-088-730
 * Detected change in '/webser/python/recmdcstbao/myapp/models.py', reloading
pbkdf2:sha256:50000$7JabfEg4$302e14d9720e8e4453b4812a9481971c437867fce293db92781823da722939e6
 * Restarting with stat
 * Debugger is active!
 * Debugger PIN: 198-088-730
 * Detected change in '/webser/python/recmdcstbao/myapp/models.py', reloading
pbkdf2:sha256:50000$dW7voYIU$2fe33f74a42b9f9475dd8700e1447b9ef3c91df10cc16913cd182c4d036f5f75
 * Restarting with stat
 * Debugger is active!
 * Debugger PIN: 198-088-730
 * Detected change in '/webser/python/recmdcstbao/myapp/models.py', reloading
pbkdf2:sha256:50000$q1YlpEYJ$7ccc894a9d4e4fcc5fcff7994036a25a2af2f1b3e78566b1f9ef260106046f08
 * Restarting with stat
 * Debugger is active!
 * Debugger PIN: 198-088-730
/Library/Python/2.7/site-packages/sqlalchemy/sql/compiler.py:624: SAWarning: Can't resolve label reference 'created_time desc'; converting to text() (this warning may be suppressed after 10 occurrences)
  util.ellipses_string(element.element))
127.0.0.1 - - [01/Jul/2017 16:45:06] "GET /api/company/list HTTP/1.0" 200 -
127.0.0.1 - - [01/Jul/2017 16:45:07] "GET /api/company/list HTTP/1.0" 200 -
127.0.0.1 - - [01/Jul/2017 16:47:34] "GET /api/company/list HTTP/1.0" 200 -
127.0.0.1 - - [01/Jul/2017 16:47:35] "GET /api/company/list HTTP/1.0" 200 -
127.0.0.1 - - [01/Jul/2017 16:47:59] "GET /api/company/list HTTP/1.0" 200 -
127.0.0.1 - - [01/Jul/2017 16:48:49] "GET /api/company/list HTTP/1.0" 200 -
127.0.0.1 - - [01/Jul/2017 16:49:28] "GET /api/company/list HTTP/1.0" 200 -
127.0.0.1 - - [01/Jul/2017 16:50:02] "GET /api/company/list HTTP/1.0" 200 -
127.0.0.1 - - [01/Jul/2017 16:51:19] "GET /api/company/list HTTP/1.0" 200 -
127.0.0.1 - - [01/Jul/2017 16:51:19] "GET /api/company/list HTTP/1.0" 200 -
127.0.0.1 - - [01/Jul/2017 16:51:59] "GET /api/company/list HTTP/1.0" 200 -
127.0.0.1 - - [01/Jul/2017 16:52:30] "GET /api/company/list HTTP/1.0" 200 -
127.0.0.1 - - [01/Jul/2017 16:52:33] "GET /api/company/list HTTP/1.0" 200 -
127.0.0.1 - - [01/Jul/2017 16:52:54] "GET /api/company/list HTTP/1.0" 200 -
127.0.0.1 - - [01/Jul/2017 16:53:40] "GET /api/company/list HTTP/1.0" 200 -
127.0.0.1 - - [01/Jul/2017 16:53:41] "GET /api/company/list HTTP/1.0" 200 -
127.0.0.1 - - [01/Jul/2017 16:54:02] "GET /api/company/list HTTP/1.0" 200 -
127.0.0.1 - - [01/Jul/2017 16:54:03] "GET /api/company/list HTTP/1.0" 200 -
 * Detected change in '/webser/python/recmdcstbao/myapp/views/customer.py', reloading
pbkdf2:sha256:50000$39RrhccY$0f9f4125bf79b7f0fc3732e155caee2e2987243e2a3b56466c8313884b3915e8
 * Restarting with stat
Traceback (most recent call last):
  File "index.py", line 6, in <module>
    from myapp import app
  File "/webser/python/recmdcstbao/myapp/__init__.py", line 15, in <module>
    from views import *
  File "/webser/python/recmdcstbao/myapp/views/__init__.py", line 5, in <module>
    from customer import *
  File "/webser/python/recmdcstbao/myapp/views/customer.py", line 34
    def 
       ^
SyntaxError: invalid syntax
pbkdf2:sha256:50000$xp6hXQdJ$52238b323f3519883999b8a49502c94becb9b7c92a69c512037a039f5f630e1a
 * Running on http://0.0.0.0:5000/ (Press CTRL+C to quit)
 * Restarting with stat
 * Debugger is active!
 * Debugger PIN: 198-088-730
/Library/Python/2.7/site-packages/sqlalchemy/sql/compiler.py:624: SAWarning: Can't resolve label reference 'created_time desc'; converting to text() (this warning may be suppressed after 10 occurrences)
  util.ellipses_string(element.element))
127.0.0.1 - - [01/Jul/2017 16:56:05] "GET /api/company/list HTTP/1.0" 200 -
127.0.0.1 - - [01/Jul/2017 16:56:05] "GET /api/company/list HTTP/1.0" 200 -
127.0.0.1 - - [01/Jul/2017 16:56:10] "GET /api/company/list HTTP/1.0" 200 -
127.0.0.1 - - [01/Jul/2017 16:56:31] "GET /api/company/list HTTP/1.0" 200 -
127.0.0.1 - - [01/Jul/2017 16:56:32] "GET /api/company/list HTTP/1.0" 200 -
127.0.0.1 - - [01/Jul/2017 16:56:56] "GET /api/company/list HTTP/1.0" 200 -
127.0.0.1 - - [01/Jul/2017 16:57:03] "GET /api/company/list HTTP/1.0" 200 -
 * Detected change in '/webser/python/recmdcstbao/myapp/views/customer.py', reloading
pbkdf2:sha256:50000$hBlgAA34$1b7cbae94c326b88c1c047355bd3bb5013329eee5073ce85810ab6cc4d3fac17
 * Restarting with stat
 * Debugger is active!
 * Debugger PIN: 198-088-730
 * Detected change in '/webser/python/recmdcstbao/myapp/views/customer.py', reloading
pbkdf2:sha256:50000$jsmZrYWV$63bfbe325156343134dec1e61ce3b543b789267566925bdfa4bcaf5e88ac83a2
 * Restarting with stat
Traceback (most recent call last):
  File "index.py", line 6, in <module>
    from myapp import app
  File "/webser/python/recmdcstbao/myapp/__init__.py", line 15, in <module>
    from views import *
  File "/webser/python/recmdcstbao/myapp/views/__init__.py", line 5, in <module>
    from customer import *
  File "/webser/python/recmdcstbao/myapp/views/customer.py", line 36
    
                ^
SyntaxError: invalid syntax
pbkdf2:sha256:50000$8ASvp8qp$46746c2faec9fb793f290cb53cf1934c4edaa275c4d7295bddb59e33cdac5a00
Traceback (most recent call last):
  File "index.py", line 6, in <module>
    from myapp import app
  File "/webser/python/recmdcstbao/myapp/__init__.py", line 15, in <module>
    from views import *
  File "/webser/python/recmdcstbao/myapp/views/__init__.py", line 5, in <module>
    from customer import *
  File "/webser/python/recmdcstbao/myapp/views/customer.py", line 36
    
                ^
SyntaxError: invalid syntax
Traceback (most recent call last):
  File "index.py", line 6, in <module>
    from myapp import app
  File "/webser/python/recmdcstbao/myapp/__init__.py", line 15, in <module>
    from views import *
  File "/webser/python/recmdcstbao/myapp/views/__init__.py", line 5, in <module>
    from customer import *
  File "/webser/python/recmdcstbao/myapp/views/customer.py", line 36
    
                ^
SyntaxError: invalid syntax
Traceback (most recent call last):
  File "index.py", line 6, in <module>
    from myapp import app
  File "/webser/python/recmdcstbao/myapp/__init__.py", line 15, in <module>
    from views import *
  File "/webser/python/recmdcstbao/myapp/views/__init__.py", line 5, in <module>
    from customer import *
  File "/webser/python/recmdcstbao/myapp/views/customer.py", line 36
    
                ^
SyntaxError: invalid syntax
 * Running on http://0.0.0.0:5000/ (Press CTRL+C to quit)
 * Restarting with stat
 * Debugger is active!
 * Debugger PIN: 198-088-730
127.0.0.1 - - [01/Jul/2017 16:58:47] "POST /api/customer/save HTTP/1.0" 500 -
Traceback (most recent call last):
  File "/Library/Python/2.7/site-packages/flask/app.py", line 1997, in __call__
    return self.wsgi_app(environ, start_response)
  File "/Library/Python/2.7/site-packages/flask/app.py", line 1985, in wsgi_app
    response = self.handle_exception(e)
  File "/Library/Python/2.7/site-packages/flask/app.py", line 1540, in handle_exception
    reraise(exc_type, exc_value, tb)
  File "/Library/Python/2.7/site-packages/flask/app.py", line 1982, in wsgi_app
    response = self.full_dispatch_request()
  File "/Library/Python/2.7/site-packages/flask/app.py", line 1614, in full_dispatch_request
    rv = self.handle_user_exception(e)
  File "/Library/Python/2.7/site-packages/flask/app.py", line 1517, in handle_user_exception
    reraise(exc_type, exc_value, tb)
  File "/Library/Python/2.7/site-packages/flask/app.py", line 1612, in full_dispatch_request
    rv = self.dispatch_request()
  File "/Library/Python/2.7/site-packages/flask/app.py", line 1598, in dispatch_request
    return self.view_functions[rule.endpoint](**req.view_args)
  File "/webser/python/recmdcstbao/myapp/views/customer.py", line 31, in save
    return lib.params.response_std(db.session.id)
AttributeError: 'scoped_session' object has no attribute 'id'
/Library/Python/2.7/site-packages/sqlalchemy/sql/compiler.py:624: SAWarning: Can't resolve label reference 'created_time desc'; converting to text() (this warning may be suppressed after 10 occurrences)
  util.ellipses_string(element.element))
127.0.0.1 - - [01/Jul/2017 16:59:12] "GET /api/company/list HTTP/1.0" 200 -
 * Detected change in '/webser/python/recmdcstbao/myapp/views/customer.py', reloading
pbkdf2:sha256:50000$0A0ZmVar$aaf52cc5c18efd845aaa5c8f65c695dfb267a697a8dae9a28ad7b5b66444e63f
 * Restarting with stat
 * Debugger is active!
 * Debugger PIN: 198-088-730
 * Detected change in '/webser/python/recmdcstbao/myapp/views/customer.py', reloading
pbkdf2:sha256:50000$jgIGB9Rs$337301471fb5eba74660e166ef25b6fa992210b03ec244e8430c0032b6fbcd57
 * Restarting with stat
 * Debugger is active!
 * Debugger PIN: 198-088-730
127.0.0.1 - - [01/Jul/2017 17:00:25] "POST /api/customer/save HTTP/1.0" 200 -
127.0.0.1 - - [01/Jul/2017 17:00:31] "POST /api/customer/save HTTP/1.0" 200 -
 * Detected change in '/webser/python/recmdcstbao/myapp/views/customer.py', reloading
pbkdf2:sha256:50000$xz4FXadg$5fa8ac22e28aeb396d8bf473f99491e528c518cf090a016fcd4971f0a1d46bfd
 * Restarting with stat
 * Debugger is active!
 * Debugger PIN: 198-088-730
/Library/Python/2.7/site-packages/sqlalchemy/sql/compiler.py:624: SAWarning: Can't resolve label reference 'created_time desc'; converting to text() (this warning may be suppressed after 10 occurrences)
  util.ellipses_string(element.element))
127.0.0.1 - - [01/Jul/2017 17:00:49] "GET /api/company/list HTTP/1.0" 200 -
 * Detected change in '/webser/python/recmdcstbao/myapp/views/customer.py', reloading
pbkdf2:sha256:50000$EPxhYZpp$3ad4435c4ef1d9e9cfadbbe2dc47b9b9e40a0819c71e016618cc249bde544ca6
 * Restarting with stat
 * Debugger is active!
 * Debugger PIN: 198-088-730
127.0.0.1 - - [01/Jul/2017 17:02:45] "POST /api/customer/save HTTP/1.0" 200 -
127.0.0.1 - - [01/Jul/2017 17:02:49] "POST /api/customer/save HTTP/1.0" 200 -
 * Detected change in '/webser/python/recmdcstbao/myapp/views/customer.py', reloading
pbkdf2:sha256:50000$kgttDscO$d8d434ea724f41146c29b20ce5dd3140a9a915bfaa6e8ef2ce76860d3b8d5401
 * Restarting with stat
Traceback (most recent call last):
  File "index.py", line 6, in <module>
    from myapp import app
  File "/webser/python/recmdcstbao/myapp/__init__.py", line 15, in <module>
    from views import *
  File "/webser/python/recmdcstbao/myapp/views/__init__.py", line 5, in <module>
    from customer import *
  File "/webser/python/recmdcstbao/myapp/views/customer.py", line 34
    
                                                      ^
SyntaxError: invalid syntax
pbkdf2:sha256:50000$P5jvolYD$0bb648d5090919b975147685e76b6a07e19319baf00523d86e6942e9b28fe178
 * Running on http://0.0.0.0:5000/ (Press CTRL+C to quit)
 * Restarting with stat
 * Debugger is active!
 * Debugger PIN: 198-088-730
127.0.0.1 - - [01/Jul/2017 17:04:47] "POST /api/customer/recommend HTTP/1.0" 200 -
/Library/Python/2.7/site-packages/sqlalchemy/sql/compiler.py:624: SAWarning: Can't resolve label reference 'created_time desc'; converting to text() (this warning may be suppressed after 10 occurrences)
  util.ellipses_string(element.element))
127.0.0.1 - - [01/Jul/2017 17:06:29] "GET /api/company/list HTTP/1.0" 200 -
 * Detected change in '/webser/python/recmdcstbao/myapp/views/customer.py', reloading
pbkdf2:sha256:50000$jZahx7yn$51e902348e98fcdc02c4c7b673b11296986b56ce19cac745efcd43133b175d23
 * Restarting with stat
 * Debugger is active!
 * Debugger PIN: 198-088-730
 * Detected change in '/webser/python/recmdcstbao/myapp/views/customer.py', reloading
pbkdf2:sha256:50000$Vgd8MAKI$f3332c487907eae6c720ed0999056d9dc5f463b798852c0f1cb4d9c3a0d782da
 * Restarting with stat
Traceback (most recent call last):
  File "index.py", line 6, in <module>
    from myapp import app
  File "/webser/python/recmdcstbao/myapp/__init__.py", line 15, in <module>
    from views import *
  File "/webser/python/recmdcstbao/myapp/views/__init__.py", line 5, in <module>
    from customer import *
  File "/webser/python/recmdcstbao/myapp/views/customer.py", line 45
    except Exception, e:
         ^
IndentationError: expected an indented block
pbkdf2:sha256:50000$1jcukb7v$6b7ca192577c21dbee8cbe5c4151539823523141a5dad7efdd35f23e412810dd
 * Running on http://0.0.0.0:5000/ (Press CTRL+C to quit)
 * Restarting with stat
 * Debugger is active!
 * Debugger PIN: 198-088-730
127.0.0.1 - - [01/Jul/2017 17:10:53] "POST /api/customer/save HTTP/1.0" 200 -
/Library/Python/2.7/site-packages/sqlalchemy/sql/compiler.py:624: SAWarning: Can't resolve label reference 'created_time desc'; converting to text() (this warning may be suppressed after 10 occurrences)
  util.ellipses_string(element.element))
127.0.0.1 - - [01/Jul/2017 17:11:01] "GET /api/company/list HTTP/1.0" 200 -
127.0.0.1 - - [01/Jul/2017 17:11:01] "POST /api/customer/save HTTP/1.0" 200 -
127.0.0.1 - - [01/Jul/2017 17:11:19] "GET /api/company/list HTTP/1.0" 200 -
 * Detected change in '/webser/python/recmdcstbao/myapp/views/customer.py', reloading
pbkdf2:sha256:50000$MECedOt8$04dbaecc5e1607934b0c7eb4c5a341e4670deca6227d6ae837d7a2b5135d4c8e
 * Restarting with stat
 * Debugger is active!
 * Debugger PIN: 198-088-730
/Library/Python/2.7/site-packages/sqlalchemy/sql/compiler.py:624: SAWarning: Can't resolve label reference 'created_time desc'; converting to text() (this warning may be suppressed after 10 occurrences)
  util.ellipses_string(element.element))
127.0.0.1 - - [01/Jul/2017 17:11:37] "GET /api/company/list HTTP/1.0" 200 -
127.0.0.1 - - [01/Jul/2017 17:12:16] "GET /api/company/list HTTP/1.0" 200 -
 * Detected change in '/webser/python/recmdcstbao/myapp/views/customer.py', reloading
pbkdf2:sha256:50000$PjAeb4iR$53a916b2b6b69498ba06818c06210247569178be6f298f6b78b3c8a51b7c19f2
 * Restarting with stat
Traceback (most recent call last):
  File "index.py", line 6, in <module>
    from myapp import app
  File "/webser/python/recmdcstbao/myapp/__init__.py", line 15, in <module>
    from views import *
  File "/webser/python/recmdcstbao/myapp/views/__init__.py", line 5, in <module>
    from customer import *
  File "/webser/python/recmdcstbao/myapp/views/customer.py", line 32
    return lib.params.response_std([])
         ^
SyntaxError: invalid syntax
pbkdf2:sha256:50000$Pii0Xie4$4d0124faad99facde490b86c22ad545aed5eb1f337532908f68210266e8db669
Traceback (most recent call last):
  File "index.py", line 6, in <module>
    from myapp import app
  File "/webser/python/recmdcstbao/myapp/__init__.py", line 15, in <module>
    from views import *
  File "/webser/python/recmdcstbao/myapp/views/__init__.py", line 5, in <module>
    from customer import *
  File "/webser/python/recmdcstbao/myapp/views/customer.py", line 31
    customer_id = request.form[]
                               ^
SyntaxError: invalid syntax
Traceback (most recent call last):
  File "index.py", line 6, in <module>
    from myapp import app
  File "/webser/python/recmdcstbao/myapp/__init__.py", line 15, in <module>
    from views import *
  File "/webser/python/recmdcstbao/myapp/views/__init__.py", line 5, in <module>
    from customer import *
  File "/webser/python/recmdcstbao/myapp/views/customer.py", line 33
    return lib.params.response_std([])
         ^
SyntaxError: invalid syntax
 * Running on http://0.0.0.0:5000/ (Press CTRL+C to quit)
 * Restarting with stat
 * Debugger is active!
 * Debugger PIN: 198-088-730
/Library/Python/2.7/site-packages/sqlalchemy/sql/compiler.py:624: SAWarning: Can't resolve label reference 'created_time desc'; converting to text() (this warning may be suppressed after 10 occurrences)
  util.ellipses_string(element.element))
127.0.0.1 - - [01/Jul/2017 17:18:47] "GET /api/company/list HTTP/1.0" 200 -
127.0.0.1 - - [01/Jul/2017 17:19:22] "GET /api/company/list HTTP/1.0" 200 -
